#VRML_SIM R2025a utf8
# license: Apache License 2.0
# license url: http://www.apache.org/licenses/LICENSE-2.0
# This is a proto file for Webots for the H12
# Extracted from: /home/rick/h1_2.urdf

PROTO H12 [
  field  SFVec3f     translation     0 0 1.6
  field  SFRotation  rotation        0 0 1 0
  field  SFString    name            "H12"  # Is `Robot.name`.
  field  SFString    controller      "generic" # Is `Robot.controller`.
  field  MFString    controllerArgs  []     # Is `Robot.controllerArgs`.
  field  SFString    customData      ""     # Is `Robot.customData`.
  field  SFBool      supervisor      FALSE  # Is `Robot.supervisor`.
  field  SFBool      synchronization TRUE   # Is `Robot.synchronization`.
  field  SFBool      selfCollision   FALSE  # Is `Robot.selfCollision`.
]
{
  Robot {
    translation IS translation
    rotation IS rotation
    controller IS controller
    controllerArgs IS controllerArgs
    customData IS customData
    supervisor IS supervisor
    synchronization IS synchronization
    selfCollision IS selfCollision
    children [
      Shape {
        appearance DEF dark PBRAppearance {
          baseColor 0.100000 0.100000 0.100000
          roughness 1.000000
          metalness 0
        }
        geometry DEF pelvis Mesh {
          url "h1_2_description/meshes/pelvis.STL"
        }
      }
      HingeJoint {
        jointParameters HingeJointParameters {
          axis 0.000000 0.000000 1.000000
          anchor 0.000000 0.087500 -0.163200
        }
        device [
          RotationalMotor {
            name "left_hip_yaw_joint"
            maxVelocity 23.0
            minPosition -0.43
            maxPosition 0.43
            maxTorque 200.0
          }
          PositionSensor {
            name "left_hip_yaw_joint_sensor"
          }
        ]
        endPoint DEF left_hip_yaw_link Solid {
          translation 0.000000 0.087500 -0.163200
          children [
            Shape {
              appearance USE dark
              geometry DEF left_hip_yaw_link Mesh {
                url "h1_2_description/meshes/left_hip_yaw_link.STL"
              }
            }
            HingeJoint {
              jointParameters HingeJointParameters {
                axis 0.000000 1.000000 0.000000
                anchor 0.000000 0.075500 0.000000
              }
              device [
                RotationalMotor {
                  name "left_hip_pitch_joint"
                  maxVelocity 23.0
                  minPosition -3.14
                  maxPosition 2.5
                  maxTorque 200.0
                }
                PositionSensor {
                  name "left_hip_pitch_joint_sensor"
                }
              ]
              endPoint DEF left_hip_pitch_link Solid {
                translation 0.000000 0.075500 0.000000
                children [
                  Shape {
                    appearance USE dark
                    geometry DEF left_hip_pitch_link Mesh {
                      url "h1_2_description/meshes/left_hip_pitch_link.STL"
                    }
                  }
                  HingeJoint {
                    jointParameters HingeJointParameters {
                    }
                    device [
                      RotationalMotor {
                        name "left_hip_roll_joint"
                        maxVelocity 23.0
                        minPosition -0.43
                        maxPosition 3.14
                        maxTorque 200.0
                      }
                      PositionSensor {
                        name "left_hip_roll_joint_sensor"
                      }
                    ]
                    endPoint DEF left_hip_roll_link Solid {
                      children [
                        Shape {
                          appearance USE dark
                          geometry DEF left_hip_roll_link Mesh {
                            url "h1_2_description/meshes/left_hip_roll_link.STL"
                          }
                        }
                        HingeJoint {
                          jointParameters HingeJointParameters {
                            axis 0.000000 1.000000 0.000000
                            anchor 0.000000 0.000000 -0.400000
                          }
                          device [
                            RotationalMotor {
                              name "left_knee_joint"
                              maxVelocity 14.0
                              minPosition -0.12
                              maxPosition 2.19
                              maxTorque 300.0
                            }
                            PositionSensor {
                              name "left_knee_joint_sensor"
                            }
                          ]
                          endPoint DEF left_knee_link Solid {
                            translation 0.000000 0.000000 -0.400000
                            children [
                              Shape {
                                appearance USE dark
                                geometry DEF left_knee_link Mesh {
                                  url "h1_2_description/meshes/left_knee_link.STL"
                                }
                              }
                              HingeJoint {
                                jointParameters HingeJointParameters {
                                  axis 0.000000 1.000000 0.000000
                                  anchor 0.000000 0.000000 -0.400000
                                }
                                device [
                                  RotationalMotor {
                                    name "left_ankle_pitch_joint"
                                    maxVelocity 9.0
                                    minPosition -0.897334
                                    maxPosition 0.523598
                                    maxTorque 60.0
                                  }
                                  PositionSensor {
                                    name "left_ankle_pitch_joint_sensor"
                                  }
                                ]
                                endPoint DEF left_ankle_pitch_link Solid {
                                  translation 0.000000 0.000000 -0.400000
                                  children [
                                    Shape {
                                      appearance USE dark
                                      geometry DEF left_ankle_pitch_link Mesh {
                                        url "h1_2_description/meshes/left_ankle_pitch_link.STL"
                                      }
                                    }
                                    HingeJoint {
                                      jointParameters HingeJointParameters {
                                        anchor 0.000000 0.000000 -0.020000
                                      }
                                      device [
                                        RotationalMotor {
                                          name "left_ankle_roll_joint"
                                          maxVelocity 9.0
                                          minPosition -0.261799
                                          maxPosition 0.261799
                                          maxTorque 40.0
                                        }
                                        PositionSensor {
                                          name "left_ankle_roll_joint_sensor"
                                        }
                                      ]
                                      endPoint DEF left_ankle_roll_link Solid {
                                        translation 0.000000 0.000000 -0.020000
                                        children [
                                          Shape {
                                            appearance USE dark
                                            geometry DEF left_ankle_roll_link Mesh {
                                              url "h1_2_description/meshes/left_ankle_roll_link.STL"
                                            }
                                          }
                                        ]
                                        name "left_ankle_roll_link"
                                        boundingObject USE left_ankle_roll_link
                                        physics Physics {
                                          density -1
                                          mass 0.747000
                                          centerOfMass [ 0.029589 0.000000 -0.015973 ]
                                          inertiaMatrix [
                                            6.488300e-04 3.435339e-03 3.583259e-03
                                            0.000000e+00 1.583800e-04 0.000000e+00
                                          ]
                                        }
                                      }
                                    }
                                  ]
                                  name "left_ankle_pitch_link"
                                  boundingObject USE left_ankle_pitch_link
                                  physics Physics {
                                    density -1
                                    mass 0.102000
                                    centerOfMass [ -0.000294 0.000000 -0.010794 ]
                                    inertiaMatrix [
                                      2.394400e-05 2.183700e-05 1.341400e-05
                                      0.000000e+00 1.210000e-07 0.000000e+00
                                    ]
                                  }
                                }
                              }
                            ]
                            name "left_knee_link"
                            boundingObject Cylinder {
                              radius 0.02
                              height 0.2
                            }
                            physics Physics {
                              density -1
                              mass 3.839000
                              centerOfMass [ 0.000179 0.000121 -0.168936 ]
                              inertiaMatrix [
                                3.900236e-02 3.904238e-02 5.029829e-03
                                -7.236400e-05 -7.945060e-04 -1.866300e-05
                              ]
                            }
                          }
                        }
                      ]
                      name "left_hip_roll_link"
                      boundingObject Cylinder {
                        radius 0.02
                        height 0.01
                      }
                      physics Physics {
                        density -1
                        mass 4.962000
                        centerOfMass [ 0.004171 -0.008576 -0.194509 ]
                        inertiaMatrix [
                          4.630587e-02 4.795540e-02 8.914518e-03
                          -3.226260e-04 -1.199703e-03 2.881470e-04
                        ]
                      }
                    }
                  }
                ]
                name "left_hip_pitch_link"
                boundingObject Cylinder {
                  radius 0.02
                  height 0.2
                }
                physics Physics {
                  density -1
                  mass 2.920000
                  centerOfMass [ -0.007810 -0.004724 -0.000063 ]
                  inertiaMatrix [
                    5.594700e-03 3.862581e-03 4.450563e-03
                    1.433080e-04 -1.184700e-05 -9.607000e-06
                  ]
                }
              }
            }
          ]
          name "left_hip_yaw_link"
          boundingObject Cylinder {
            radius 0.01
            height 0.02
          }
          physics Physics {
            density -1
            mass 2.829000
            centerOfMass [ 0.000000 -0.026197 0.006647 ]
            inertiaMatrix [
              4.553605e-03 5.688730e-03 3.548907e-03
              5.000000e-09 8.170000e-07 -3.451570e-04
            ]
          }
        }
      }
      HingeJoint {
        jointParameters HingeJointParameters {
          axis 0.000000 0.000000 1.000000
          anchor 0.000000 -0.087500 -0.163200
        }
        device [
          RotationalMotor {
            name "right_hip_yaw_joint"
            maxVelocity 23.0
            minPosition -0.43
            maxPosition 0.43
            maxTorque 200.0
          }
          PositionSensor {
            name "right_hip_yaw_joint_sensor"
          }
        ]
        endPoint DEF right_hip_yaw_link Solid {
          translation 0.000000 -0.087500 -0.163200
          children [
            Shape {
              appearance USE dark
              geometry DEF right_hip_yaw_link Mesh {
                url "h1_2_description/meshes/right_hip_yaw_link.STL"
              }
            }
            HingeJoint {
              jointParameters HingeJointParameters {
                axis 0.000000 1.000000 0.000000
                anchor 0.000000 -0.075500 0.000000
              }
              device [
                RotationalMotor {
                  name "right_hip_pitch_joint"
                  maxVelocity 23.0
                  minPosition -3.14
                  maxPosition 2.5
                  maxTorque 200.0
                }
                PositionSensor {
                  name "right_hip_pitch_joint_sensor"
                }
              ]
              endPoint DEF right_hip_pitch_link Solid {
                translation 0.000000 -0.075500 0.000000
                children [
                  Shape {
                    appearance USE dark
                    geometry DEF right_hip_pitch_link Mesh {
                      url "h1_2_description/meshes/right_hip_pitch_link.STL"
                    }
                  }
                  HingeJoint {
                    jointParameters HingeJointParameters {
                    }
                    device [
                      RotationalMotor {
                        name "right_hip_roll_joint"
                        maxVelocity 23.0
                        minPosition -3.14
                        maxPosition 0.43
                        maxTorque 200.0
                      }
                      PositionSensor {
                        name "right_hip_roll_joint_sensor"
                      }
                    ]
                    endPoint DEF right_hip_roll_link Solid {
                      children [
                        Shape {
                          appearance USE dark
                          geometry DEF right_hip_roll_link Mesh {
                            url "h1_2_description/meshes/right_hip_roll_link.STL"
                          }
                        }
                        HingeJoint {
                          jointParameters HingeJointParameters {
                            axis 0.000000 1.000000 0.000000
                            anchor 0.000000 0.000000 -0.400000
                          }
                          device [
                            RotationalMotor {
                              name "right_knee_joint"
                              maxVelocity 14.0
                              minPosition -0.12
                              maxPosition 2.19
                              maxTorque 300.0
                            }
                            PositionSensor {
                              name "right_knee_joint_sensor"
                            }
                          ]
                          endPoint DEF right_knee_link Solid {
                            translation 0.000000 0.000000 -0.400000
                            children [
                              Shape {
                                appearance USE dark
                                geometry DEF right_knee_link Mesh {
                                  url "h1_2_description/meshes/right_knee_link.STL"
                                }
                              }
                              HingeJoint {
                                jointParameters HingeJointParameters {
                                  axis 0.000000 1.000000 0.000000
                                  anchor 0.000000 0.000000 -0.400000
                                }
                                device [
                                  RotationalMotor {
                                    name "right_ankle_pitch_joint"
                                    maxVelocity 9.0
                                    minPosition -0.897334
                                    maxPosition 0.523598
                                    maxTorque 60.0
                                  }
                                  PositionSensor {
                                    name "right_ankle_pitch_joint_sensor"
                                  }
                                ]
                                endPoint DEF right_ankle_pitch_link Solid {
                                  translation 0.000000 0.000000 -0.400000
                                  children [
                                    Shape {
                                      appearance USE dark
                                      geometry DEF right_ankle_pitch_link Mesh {
                                        url "h1_2_description/meshes/right_ankle_pitch_link.STL"
                                      }
                                    }
                                    HingeJoint {
                                      jointParameters HingeJointParameters {
                                        anchor 0.000000 0.000000 -0.020000
                                      }
                                      device [
                                        RotationalMotor {
                                          name "right_ankle_roll_joint"
                                          maxVelocity 9.0
                                          minPosition -0.261799
                                          maxPosition 0.261799
                                          maxTorque 40.0
                                        }
                                        PositionSensor {
                                          name "right_ankle_roll_joint_sensor"
                                        }
                                      ]
                                      endPoint DEF right_ankle_roll_link Solid {
                                        translation 0.000000 0.000000 -0.020000
                                        children [
                                          Shape {
                                            appearance USE dark
                                            geometry DEF right_ankle_roll_link Mesh {
                                              url "h1_2_description/meshes/right_ankle_roll_link.STL"
                                            }
                                          }
                                        ]
                                        name "right_ankle_roll_link"
                                        boundingObject USE right_ankle_roll_link
                                        physics Physics {
                                          density -1
                                          mass 0.747000
                                          centerOfMass [ 0.029589 0.000000 -0.015973 ]
                                          inertiaMatrix [
                                            6.488300e-04 3.435339e-03 3.583259e-03
                                            0.000000e+00 1.583800e-04 0.000000e+00
                                          ]
                                        }
                                      }
                                    }
                                  ]
                                  name "right_ankle_pitch_link"
                                  boundingObject USE right_ankle_pitch_link
                                  physics Physics {
                                    density -1
                                    mass 0.102000
                                    centerOfMass [ -0.000294 0.000000 -0.010794 ]
                                    inertiaMatrix [
                                      2.394400e-05 2.183700e-05 1.341400e-05
                                      0.000000e+00 1.210000e-07 0.000000e+00
                                    ]
                                  }
                                }
                              }
                            ]
                            name "right_knee_link"
                            boundingObject Cylinder {
                              radius 0.02
                              height 0.2
                            }
                            physics Physics {
                              density -1
                              mass 3.839000
                              centerOfMass [ 0.000179 -0.000121 -0.168936 ]
                              inertiaMatrix [
                                3.900236e-02 3.904238e-02 5.029829e-03
                                7.236400e-05 -7.945060e-04 1.866300e-05
                              ]
                            }
                          }
                        }
                      ]
                      name "right_hip_roll_link"
                      boundingObject Cylinder {
                        radius 0.02
                        height 0.01
                      }
                      physics Physics {
                        density -1
                        mass 4.962000
                        centerOfMass [ 0.004171 0.008576 -0.194509 ]
                        inertiaMatrix [
                          4.630587e-02 4.795540e-02 8.914518e-03
                          3.226260e-04 -1.199703e-03 -2.881470e-04
                        ]
                      }
                    }
                  }
                ]
                name "right_hip_pitch_link"
                boundingObject Cylinder {
                  radius 0.02
                  height 0.2
                }
                physics Physics {
                  density -1
                  mass 2.920000
                  centerOfMass [ -0.007810 0.004724 -0.000063 ]
                  inertiaMatrix [
                    5.594700e-03 3.862581e-03 4.450563e-03
                    -1.433080e-04 -1.184700e-05 9.607000e-06
                  ]
                }
              }
            }
          ]
          name "right_hip_yaw_link"
          boundingObject Cylinder {
            radius 0.01
            height 0.02
          }
          physics Physics {
            density -1
            mass 2.829000
            centerOfMass [ 0.000000 0.026197 0.006647 ]
            inertiaMatrix [
              4.553605e-03 5.688730e-03 3.548907e-03
              -5.000000e-09 8.170000e-07 3.451570e-04
            ]
          }
        }
      }
      HingeJoint {
        jointParameters HingeJointParameters {
          axis 0.000000 0.000000 1.000000
        }
        device [
          RotationalMotor {
            name "torso_joint"
            maxVelocity 23.0
            minPosition -2.35
            maxPosition 2.35
            maxTorque 200.0
          }
          PositionSensor {
            name "torso_joint_sensor"
          }
        ]
        endPoint DEF torso_link Solid {
          children [
            Shape {
              appearance USE dark
              geometry DEF torso_link Mesh {
                url "h1_2_description/meshes/torso_link.STL"
              }
            }
            HingeJoint {
              jointParameters HingeJointParameters {
                axis 0.000000 0.965926 0.258820
                anchor 0.000000 0.148060 0.423330
              }
              device [
                RotationalMotor {
                  name "left_shoulder_pitch_joint"
                  maxVelocity 9.0
                  minPosition -3.14
                  maxPosition 1.57
                  maxTorque 40.0
                }
                PositionSensor {
                  name "left_shoulder_pitch_joint_sensor"
                }
              ]
              endPoint DEF left_shoulder_pitch_link Solid {
                translation 0.000000 0.148060 0.423330
                rotation 1.000000 0.000000 0.000000 0.261800
                children [
                  Shape {
                    appearance USE dark
                    geometry DEF left_shoulder_pitch_link Mesh {
                      url "h1_2_description/meshes/left_shoulder_pitch_link.STL"
                    }
                  }
                  HingeJoint {
                    jointParameters HingeJointParameters {
                      anchor 0.034200 0.061999 -0.006001
                    }
                    device [
                      RotationalMotor {
                        name "left_shoulder_roll_joint"
                        maxVelocity 9.0
                        minPosition -0.38
                        maxPosition 3.4
                        maxTorque 40.0
                      }
                      PositionSensor {
                        name "left_shoulder_roll_joint_sensor"
                      }
                    ]
                    endPoint DEF left_shoulder_roll_link Solid {
                      translation 0.034200 0.061999 -0.006001
                      rotation -1.000000 0.000000 0.000000 0.261800
                      children [
                        Shape {
                          appearance USE dark
                          geometry DEF left_shoulder_roll_link Mesh {
                            url "h1_2_description/meshes/left_shoulder_roll_link.STL"
                          }
                        }
                        HingeJoint {
                          jointParameters HingeJointParameters {
                            axis 0.000000 0.000000 1.000000
                            anchor -0.034200 0.000000 -0.145600
                          }
                          device [
                            RotationalMotor {
                              name "left_shoulder_yaw_joint"
                              maxVelocity 20.0
                              minPosition -2.66
                              maxPosition 3.01
                              maxTorque 18.0
                            }
                            PositionSensor {
                              name "left_shoulder_yaw_joint_sensor"
                            }
                          ]
                          endPoint DEF left_shoulder_yaw_link Solid {
                            translation -0.034200 0.000000 -0.145600
                            children [
                              Shape {
                                appearance USE dark
                                geometry DEF left_shoulder_yaw_link Mesh {
                                  url "h1_2_description/meshes/left_shoulder_yaw_link.STL"
                                }
                              }
                              HingeJoint {
                                jointParameters HingeJointParameters {
                                  axis 0.000000 1.000000 0.000000
                                  anchor 0.006000 0.032900 -0.182000
                                }
                                device [
                                  RotationalMotor {
                                    name "left_elbow_joint"
                                    maxVelocity 20.0
                                    minPosition -0.95
                                    maxPosition 3.18
                                    maxTorque 18.0
                                  }
                                  PositionSensor {
                                    name "left_elbow_joint_sensor"
                                  }
                                ]
                                endPoint DEF left_elbow_link Solid {
                                  translation 0.006000 0.032900 -0.182000
                                  children [
                                    Shape {
                                      appearance USE dark
                                      geometry DEF left_elbow_link Mesh {
                                        url "h1_2_description/meshes/left_elbow_link.STL"
                                      }
                                    }
                                    HingeJoint {
                                      jointParameters HingeJointParameters {
                                        anchor 0.121000 -0.032900 -0.011000
                                      }
                                      device [
                                        RotationalMotor {
                                          name "left_wrist_roll_joint"
                                          maxVelocity 31.4
                                          minPosition -3.01
                                          maxPosition 2.75
                                          maxTorque 19.0
                                        }
                                        PositionSensor {
                                          name "left_wrist_roll_joint_sensor"
                                        }
                                      ]
                                      endPoint DEF left_wrist_roll_link Solid {
                                        translation 0.121000 -0.032900 -0.011000
                                        children [
                                          Shape {
                                            appearance USE dark
                                            geometry DEF left_wrist_roll_link Mesh {
                                              url "h1_2_description/meshes/left_wrist_roll_link.STL"
                                            }
                                          }
                                          HingeJoint {
                                            jointParameters HingeJointParameters {
                                              axis 0.000000 1.000000 0.000000
                                              anchor 0.087000 0.000000 0.000000
                                            }
                                            device [
                                              RotationalMotor {
                                                name "left_wrist_pitch_joint"
                                                maxVelocity 31.4
                                                minPosition -0.4625
                                                maxPosition 0.4625
                                                maxTorque 19.0
                                              }
                                              PositionSensor {
                                                name "left_wrist_pitch_joint_sensor"
                                              }
                                            ]
                                            endPoint DEF left_wrist_pitch_link Solid {
                                              translation 0.087000 0.000000 0.000000
                                              children [
                                                Shape {
                                                  appearance USE dark
                                                  geometry DEF left_wrist_pitch_link Mesh {
                                                    url "h1_2_description/meshes/left_wrist_pitch_link.STL"
                                                  }
                                                }
                                                HingeJoint {
                                                  jointParameters HingeJointParameters {
                                                    axis 0.000000 0.000000 1.000000
                                                    anchor 0.020000 0.000000 0.000000
                                                  }
                                                  device [
                                                    RotationalMotor {
                                                      name "left_wrist_yaw_joint"
                                                      maxVelocity 31.4
                                                      minPosition -1.27
                                                      maxPosition 1.27
                                                      maxTorque 19.0
                                                    }
                                                    PositionSensor {
                                                      name "left_wrist_yaw_joint_sensor"
                                                    }
                                                  ]
                                                  endPoint DEF left_wrist_yaw_link Solid {
                                                    translation 0.020000 0.000000 0.000000
                                                    children [
                                                      Shape {
                                                        appearance USE dark
                                                        geometry DEF wrist_yaw_link Mesh {
                                                          url "h1_2_description/meshes/wrist_yaw_link.STL"
                                                        }
                                                      }
                                                      DEF L_hand_base_link Solid {
                                                        translation 0.054000 0.000000 0.000000
                                                        rotation 0.000000 0.000000 1.000000 1.570796
                                                        children [
                                                          Shape {
                                                            appearance USE dark
                                                            geometry DEF L_hand_base_link Mesh {
                                                              url "h1_2_description/meshes/L_hand_base_link.STL"
                                                            }
                                                          }
                                                          HingeJoint {
                                                            jointParameters HingeJointParameters {
                                                              axis 0.000004 -1.000000 0.000000
                                                              anchor -0.016960 -0.069100 0.020450
                                                            }
                                                            device [
                                                              RotationalMotor {
                                                                name "L_thumb_proximal_yaw_joint"
                                                                maxVelocity 0.5
                                                                minPosition -0.1
                                                                maxPosition 1.3
                                                                maxTorque 1.0
                                                              }
                                                              PositionSensor {
                                                                name "L_thumb_proximal_yaw_joint_sensor"
                                                              }
                                                            ]
                                                            endPoint DEF L_thumb_proximal_base Solid {
                                                              translation -0.016960 -0.069100 0.020450
                                                              rotation 0.577350 -0.577350 0.577352 2.094399
                                                              children [
                                                                Shape {
                                                                  appearance USE dark
                                                                  geometry DEF link11_L Mesh {
                                                                    url "h1_2_description/meshes/link11_L.STL"
                                                                  }
                                                                }
                                                                HingeJoint {
                                                                  jointParameters HingeJointParameters {
                                                                    axis 0.168581 -0.985688 0.000004
                                                                    anchor 0.009987 0.009824 -0.008900
                                                                  }
                                                                  device [
                                                                    RotationalMotor {
                                                                      name "L_thumb_proximal_pitch_joint"
                                                                      maxVelocity 0.5
                                                                      minPosition -0.1
                                                                      maxPosition 0.6
                                                                      maxTorque 1.0
                                                                    }
                                                                    PositionSensor {
                                                                      name "L_thumb_proximal_pitch_joint_sensor"
                                                                    }
                                                                  ]
                                                                  endPoint DEF L_thumb_proximal Solid {
                                                                    translation 0.009987 0.009824 -0.008900
                                                                    rotation -0.992869 -0.084293 0.084292 1.577956
                                                                    children [
                                                                      Shape {
                                                                        appearance USE dark
                                                                        geometry DEF link12_L Mesh {
                                                                          url "h1_2_description/meshes/link12_L.STL"
                                                                        }
                                                                      }
                                                                      HingeJoint {
                                                                        jointParameters HingeJointParameters {
                                                                          axis 0.000000 0.000000 -1.000000
                                                                          anchor 0.044070 -0.034553 -0.000800
                                                                        }
                                                                        device [
                                                                          RotationalMotor {
                                                                            name "L_thumb_intermediate_joint"
                                                                            maxVelocity 0.5
                                                                            maxPosition 0.8
                                                                            maxTorque 1.0
                                                                          }
                                                                          PositionSensor {
                                                                            name "L_thumb_intermediate_joint_sensor"
                                                                          }
                                                                        ]
                                                                        endPoint DEF L_thumb_intermediate Solid {
                                                                          translation 0.044070 -0.034553 -0.000800
                                                                          children [
                                                                            Shape {
                                                                              appearance USE dark
                                                                              geometry DEF link13_L Mesh {
                                                                                url "h1_2_description/meshes/link13_L.STL"
                                                                              }
                                                                            }
                                                                            HingeJoint {
                                                                              jointParameters HingeJointParameters {
                                                                                axis 0.000000 0.000000 -1.000000
                                                                                anchor 0.020248 -0.010156 -0.001200
                                                                              }
                                                                              device [
                                                                                RotationalMotor {
                                                                                  name "L_thumb_distal_joint"
                                                                                  maxVelocity 0.5
                                                                                  maxPosition 1.2
                                                                                  maxTorque 1.0
                                                                                }
                                                                                PositionSensor {
                                                                                  name "L_thumb_distal_joint_sensor"
                                                                                }
                                                                              ]
                                                                              endPoint DEF L_thumb_distal Solid {
                                                                                translation 0.020248 -0.010156 -0.001200
                                                                                children [
                                                                                  Shape {
                                                                                    appearance USE dark
                                                                                    geometry DEF link14_L Mesh {
                                                                                      url "h1_2_description/meshes/link14_L.STL"
                                                                                    }
                                                                                  }
                                                                                ]
                                                                                name "L_thumb_distal"
                                                                                boundingObject USE link14_L
                                                                                physics Physics {
                                                                                  density -1
                                                                                  mass 0.003344
                                                                                  centerOfMass [ 0.009289 -0.004953 -0.006003 ]
                                                                                  inertiaMatrix [
                                                                                    1.363200e-07 1.405200e-07 2.002600e-07
                                                                                    5.678700e-08 -9.193900e-11 1.214500e-10
                                                                                  ]
                                                                                }
                                                                              }
                                                                            }
                                                                          ]
                                                                          name "L_thumb_intermediate"
                                                                          boundingObject USE link13_L
                                                                          physics Physics {
                                                                            density -1
                                                                            mass 0.003784
                                                                            centerOfMass [ 0.009553 0.001628 -0.007200 ]
                                                                            inertiaMatrix [
                                                                              3.698100e-07 3.239500e-07 4.653200e-07
                                                                              9.860300e-08 -2.817300e-12 -2.802800e-12
                                                                            ]
                                                                          }
                                                                        }
                                                                      }
                                                                    ]
                                                                    name "L_thumb_proximal"
                                                                    boundingObject USE link12_L
                                                                    physics Physics {
                                                                      density -1
                                                                      mass 0.006610
                                                                      centerOfMass [ 0.021936 -0.012790 -0.008039 ]
                                                                      inertiaMatrix [
                                                                        1.569300e-06 1.735600e-06 2.787000e-06
                                                                        7.833900e-07 8.595900e-10 1.037800e-09
                                                                      ]
                                                                    }
                                                                  }
                                                                }
                                                              ]
                                                              name "L_thumb_proximal_base"
                                                              boundingObject USE link11_L
                                                              physics Physics {
                                                                density -1
                                                                mass 0.001887
                                                                centerOfMass [ 0.004882 0.000388 -0.007220 ]
                                                                inertiaMatrix [
                                                                  5.515800e-08 8.216400e-08 6.743400e-08
                                                                  -1.180300e-08 -4.674300e-09 -1.352100e-09
                                                                ]
                                                              }
                                                            }
                                                          }
                                                          HingeJoint {
                                                            jointParameters HingeJointParameters {
                                                              axis 0.000000 -0.034900 -0.999391
                                                              anchor 0.000285 -0.136530 0.032268
                                                            }
                                                            device [
                                                              RotationalMotor {
                                                                name "L_index_proximal_joint"
                                                                maxVelocity 0.5
                                                                maxPosition 1.7
                                                                maxTorque 1.0
                                                              }
                                                              PositionSensor {
                                                                name "L_index_proximal_joint_sensor"
                                                              }
                                                            ]
                                                            endPoint DEF L_index_proximal Solid {
                                                              translation 0.000285 -0.136530 0.032268
                                                              rotation -1.000000 0.000000 0.000000 0.034907
                                                              children [
                                                                Shape {
                                                                  appearance USE dark
                                                                  geometry DEF link15_L Mesh {
                                                                    url "h1_2_description/meshes/link15_L.STL"
                                                                  }
                                                                }
                                                                HingeJoint {
                                                                  jointParameters HingeJointParameters {
                                                                    axis 0.000000 0.000000 -1.000000
                                                                    anchor -0.002423 -0.032041 -0.001000
                                                                  }
                                                                  device [
                                                                    RotationalMotor {
                                                                      name "L_index_intermediate_joint"
                                                                      maxVelocity 0.5
                                                                      maxPosition 1.7
                                                                      maxTorque 1.0
                                                                    }
                                                                    PositionSensor {
                                                                      name "L_index_intermediate_joint_sensor"
                                                                    }
                                                                  ]
                                                                  endPoint DEF L_index_intermediate Solid {
                                                                    translation -0.002423 -0.032041 -0.001000
                                                                    children [
                                                                      Shape {
                                                                        appearance USE dark
                                                                        geometry DEF link16_L Mesh {
                                                                          url "h1_2_description/meshes/link16_L.STL"
                                                                        }
                                                                      }
                                                                    ]
                                                                    name "L_index_intermediate"
                                                                    boundingObject USE link16_L
                                                                    physics Physics {
                                                                      density -1
                                                                      mass 0.004568
                                                                      centerOfMass [ 0.002175 -0.019567 -0.005000 ]
                                                                      inertiaMatrix [
                                                                        7.628400e-07 9.430800e-08 7.817600e-07
                                                                        -8.063000e-08 3.679700e-13 1.574300e-13
                                                                      ]
                                                                    }
                                                                  }
                                                                }
                                                              ]
                                                              name "L_index_proximal"
                                                              boundingObject USE link15_L
                                                              physics Physics {
                                                                density -1
                                                                mass 0.004241
                                                                centerOfMass [ 0.001297 -0.011934 -0.006000 ]
                                                                inertiaMatrix [
                                                                  6.621500e-07 2.116700e-07 6.940200e-07
                                                                  1.844200e-08 1.374600e-12 -1.477300e-11
                                                                ]
                                                              }
                                                            }
                                                          }
                                                          HingeJoint {
                                                            jointParameters HingeJointParameters {
                                                              axis 0.000000 0.000000 -1.000000
                                                              anchor 0.000285 -0.137100 0.012950
                                                            }
                                                            device [
                                                              RotationalMotor {
                                                                name "L_middle_proximal_joint"
                                                                maxVelocity 0.5
                                                                maxPosition 1.7
                                                                maxTorque 1.0
                                                              }
                                                              PositionSensor {
                                                                name "L_middle_proximal_joint_sensor"
                                                              }
                                                            ]
                                                            endPoint DEF L_middle_proximal Solid {
                                                              translation 0.000285 -0.137100 0.012950
                                                              children [
                                                                Shape {
                                                                  appearance USE dark
                                                                  geometry DEF link17_L Mesh {
                                                                    url "h1_2_description/meshes/link17_L.STL"
                                                                  }
                                                                }
                                                                HingeJoint {
                                                                  jointParameters HingeJointParameters {
                                                                    axis 0.000000 0.000000 -1.000000
                                                                    anchor -0.002423 -0.032041 -0.001000
                                                                  }
                                                                  device [
                                                                    RotationalMotor {
                                                                      name "L_middle_intermediate_joint"
                                                                      maxVelocity 0.5
                                                                      maxPosition 1.7
                                                                      maxTorque 1.0
                                                                    }
                                                                    PositionSensor {
                                                                      name "L_middle_intermediate_joint_sensor"
                                                                    }
                                                                  ]
                                                                  endPoint DEF L_middle_intermediate Solid {
                                                                    translation -0.002423 -0.032041 -0.001000
                                                                    children [
                                                                      Shape {
                                                                        appearance USE dark
                                                                        geometry DEF link18_L Mesh {
                                                                          url "h1_2_description/meshes/link18_L.STL"
                                                                        }
                                                                      }
                                                                    ]
                                                                    name "L_middle_intermediate"
                                                                    boundingObject USE link18_L
                                                                    physics Physics {
                                                                      density -1
                                                                      mass 0.005040
                                                                      centerOfMass [ 0.001921 -0.020796 -0.005000 ]
                                                                      inertiaMatrix [
                                                                        9.582300e-07 1.064600e-07 9.838500e-07
                                                                        -1.142500e-07 -2.418600e-12 3.697400e-12
                                                                      ]
                                                                    }
                                                                  }
                                                                }
                                                              ]
                                                              name "L_middle_proximal"
                                                              boundingObject USE link17_L
                                                              physics Physics {
                                                                density -1
                                                                mass 0.004241
                                                                centerOfMass [ 0.001297 -0.011934 -0.006000 ]
                                                                inertiaMatrix [
                                                                  6.621500e-07 2.116700e-07 6.940200e-07
                                                                  1.844200e-08 1.229900e-12 -1.448400e-11
                                                                ]
                                                              }
                                                            }
                                                          }
                                                          HingeJoint {
                                                            jointParameters HingeJointParameters {
                                                              axis 0.000000 0.052336 -0.998630
                                                              anchor 0.000285 -0.136910 -0.006287
                                                            }
                                                            device [
                                                              RotationalMotor {
                                                                name "L_ring_proximal_joint"
                                                                maxVelocity 0.5
                                                                maxPosition 1.7
                                                                maxTorque 1.0
                                                              }
                                                              PositionSensor {
                                                                name "L_ring_proximal_joint_sensor"
                                                              }
                                                            ]
                                                            endPoint DEF L_ring_proximal Solid {
                                                              translation 0.000285 -0.136910 -0.006287
                                                              rotation 1.000000 0.000000 0.000000 0.052360
                                                              children [
                                                                Shape {
                                                                  appearance USE dark
                                                                  geometry DEF link19_L Mesh {
                                                                    url "h1_2_description/meshes/link19_L.STL"
                                                                  }
                                                                }
                                                                HingeJoint {
                                                                  jointParameters HingeJointParameters {
                                                                    axis 0.000000 0.000000 -1.000000
                                                                    anchor -0.002423 -0.032041 -0.001000
                                                                  }
                                                                  device [
                                                                    RotationalMotor {
                                                                      name "L_ring_intermediate_joint"
                                                                      maxVelocity 0.5
                                                                      maxPosition 1.7
                                                                      maxTorque 1.0
                                                                    }
                                                                    PositionSensor {
                                                                      name "L_ring_intermediate_joint_sensor"
                                                                    }
                                                                  ]
                                                                  endPoint DEF L_ring_intermediate Solid {
                                                                    translation -0.002423 -0.032041 -0.001000
                                                                    children [
                                                                      Shape {
                                                                        appearance USE dark
                                                                        geometry DEF link20_L Mesh {
                                                                          url "h1_2_description/meshes/link20_L.STL"
                                                                        }
                                                                      }
                                                                    ]
                                                                    name "L_ring_intermediate"
                                                                    boundingObject USE link20_L
                                                                    physics Physics {
                                                                      density -1
                                                                      mass 0.004568
                                                                      centerOfMass [ 0.002175 -0.019567 -0.005000 ]
                                                                      inertiaMatrix [
                                                                        7.628500e-07 9.430800e-08 7.817600e-07
                                                                        -8.063100e-08 3.347200e-14 -4.477300e-13
                                                                      ]
                                                                    }
                                                                  }
                                                                }
                                                              ]
                                                              name "L_ring_proximal"
                                                              boundingObject USE link19_L
                                                              physics Physics {
                                                                density -1
                                                                mass 0.004241
                                                                centerOfMass [ 0.001297 -0.011934 -0.006000 ]
                                                                inertiaMatrix [
                                                                  6.621500e-07 2.116700e-07 6.940200e-07
                                                                  1.844200e-08 9.605200e-13 -1.412400e-11
                                                                ]
                                                              }
                                                            }
                                                          }
                                                          HingeJoint {
                                                            jointParameters HingeJointParameters {
                                                              axis 0.000000 0.104529 -0.994522
                                                              anchor 0.000285 -0.135710 -0.025488
                                                            }
                                                            device [
                                                              RotationalMotor {
                                                                name "L_pinky_proximal_joint"
                                                                maxVelocity 0.5
                                                                maxPosition 1.7
                                                                maxTorque 1.0
                                                              }
                                                              PositionSensor {
                                                                name "L_pinky_proximal_joint_sensor"
                                                              }
                                                            ]
                                                            endPoint DEF L_pinky_proximal Solid {
                                                              translation 0.000285 -0.135710 -0.025488
                                                              rotation 1.000000 0.000000 0.000000 0.104720
                                                              children [
                                                                Shape {
                                                                  appearance USE dark
                                                                  geometry DEF link21_L Mesh {
                                                                    url "h1_2_description/meshes/link21_L.STL"
                                                                  }
                                                                }
                                                                HingeJoint {
                                                                  jointParameters HingeJointParameters {
                                                                    axis 0.000000 0.000000 -1.000000
                                                                    anchor -0.002423 -0.032041 -0.001000
                                                                  }
                                                                  device [
                                                                    RotationalMotor {
                                                                      name "L_pinky_intermediate_joint"
                                                                      maxVelocity 0.5
                                                                      maxPosition 1.7
                                                                      maxTorque 1.0
                                                                    }
                                                                    PositionSensor {
                                                                      name "L_pinky_intermediate_joint_sensor"
                                                                    }
                                                                  ]
                                                                  endPoint DEF L_pinky_intermediate Solid {
                                                                    translation -0.002423 -0.032041 -0.001000
                                                                    children [
                                                                      Shape {
                                                                        appearance USE dark
                                                                        geometry DEF link22_L Mesh {
                                                                          url "h1_2_description/meshes/link22_L.STL"
                                                                        }
                                                                      }
                                                                    ]
                                                                    name "L_pinky_intermediate"
                                                                    boundingObject USE link22_L
                                                                    physics Physics {
                                                                      density -1
                                                                      mass 0.003604
                                                                      centerOfMass [ 0.002479 -0.016208 -0.005000 ]
                                                                      inertiaMatrix [
                                                                        4.392300e-07 7.031500e-08 4.488100e-07
                                                                        -4.135500e-08 1.226300e-12 3.131100e-12
                                                                      ]
                                                                    }
                                                                  }
                                                                }
                                                              ]
                                                              name "L_pinky_proximal"
                                                              boundingObject USE link21_L
                                                              physics Physics {
                                                                density -1
                                                                mass 0.004241
                                                                centerOfMass [ 0.001297 -0.011934 -0.006000 ]
                                                                inertiaMatrix [
                                                                  6.621500e-07 2.116700e-07 6.940200e-07
                                                                  1.844200e-08 1.027900e-12 -1.427700e-11
                                                                ]
                                                              }
                                                            }
                                                          }
                                                        ]
                                                        name "L_hand_base_link"
                                                        boundingObject USE L_hand_base_link
                                                        physics Physics {
                                                          density -1
                                                          mass 0.141430
                                                          centerOfMass [ -0.002551 -0.066047 -0.001936 ]
                                                          inertiaMatrix [
                                                            1.234000e-04 8.383500e-05 7.723100e-05
                                                            2.199500e-06 -1.769400e-06 1.596800e-06
                                                          ]
                                                        }
                                                      }
                                                    ]
                                                    name "left_wrist_yaw_link"
                                                    physics Physics {
                                                      density -1
                                                      mass 0.124000
                                                      centerOfMass [ 0.027967 0.000096 0.000739 ]
                                                      inertiaMatrix [
                                                        1.373000e-04 1.699980e-04 8.480800e-05
                                                        -1.710000e-07 2.942000e-06 -2.500000e-08
                                                      ]
                                                    }
                                                  }
                                                }
                                              ]
                                              name "left_wrist_pitch_link"
                                              boundingObject USE left_wrist_pitch_link
                                              physics Physics {
                                                density -1
                                                mass 0.484000
                                                centerOfMass [ 0.020395 0.000036 -0.002973 ]
                                                inertiaMatrix [
                                                  7.136400e-05 6.991500e-05 7.070200e-05
                                                  3.080000e-07 1.485000e-06 -8.800000e-08
                                                ]
                                              }
                                            }
                                          }
                                        ]
                                        name "left_wrist_roll_link"
                                        boundingObject USE left_wrist_roll_link
                                        physics Physics {
                                          density -1
                                          mass 0.683000
                                          centerOfMass [ 0.035281 -0.002320 0.000337 ]
                                          inertiaMatrix [
                                            3.132750e-04 3.104120e-04 3.459980e-04
                                            1.652100e-05 -2.501000e-06 5.435000e-06
                                          ]
                                        }
                                      }
                                    }
                                  ]
                                  name "left_elbow_link"
                                  boundingObject USE left_elbow_link
                                  physics Physics {
                                    density -1
                                    mass 0.691000
                                    centerOfMass [ 0.077092 -0.028751 -0.009714 ]
                                    inertiaMatrix [
                                      3.184910e-04 8.612240e-04 8.978990e-04
                                      2.245540e-04 6.620760e-05 -2.332900e-05
                                    ]
                                  }
                                }
                              }
                            ]
                            name "left_shoulder_yaw_link"
                            boundingObject USE left_shoulder_yaw_link
                            physics Physics {
                              density -1
                              mass 1.505000
                              centerOfMass [ 0.004583 0.001128 -0.001128 ]
                              inertiaMatrix [
                                4.199000e-03 4.313900e-03 6.575500e-04
                                -1.778600e-05 1.837200e-04 9.278000e-05
                              ]
                            }
                          }
                        }
                      ]
                      name "left_shoulder_roll_link"
                      boundingObject USE left_shoulder_roll_link
                      physics Physics {
                        density -1
                        mass 1.393000
                        centerOfMass [ -0.030932 -0.000001 -0.106090 ]
                        inertiaMatrix [
                          1.840800e-03 1.934638e-03 6.177330e-04
                          3.980000e-07 -4.832400e-04 1.610000e-07
                        ]
                      }
                    }
                  }
                ]
                name "left_shoulder_pitch_link"
                boundingObject USE left_shoulder_pitch_link
                physics Physics {
                  density -1
                  mass 1.327000
                  centerOfMass [ 0.003053 0.060420 -0.005900 ]
                  inertiaMatrix [
                    5.866100e-04 3.989000e-04 5.293600e-04
                    -2.015700e-05 2.985000e-06 2.238000e-05
                  ]
                }
              }
            }
            HingeJoint {
              jointParameters HingeJointParameters {
                axis 0.000000 0.965926 -0.258820
                anchor 0.000000 -0.148060 0.423330
              }
              device [
                RotationalMotor {
                  name "right_shoulder_pitch_joint"
                  maxVelocity 9.0
                  minPosition -3.14
                  maxPosition 1.57
                  maxTorque 40.0
                }
                PositionSensor {
                  name "right_shoulder_pitch_joint_sensor"
                }
              ]
              endPoint DEF right_shoulder_pitch_link Solid {
                translation 0.000000 -0.148060 0.423330
                rotation -1.000000 0.000000 0.000000 0.261800
                children [
                  Shape {
                    appearance USE dark
                    geometry DEF right_shoulder_pitch_link Mesh {
                      url "h1_2_description/meshes/right_shoulder_pitch_link.STL"
                    }
                  }
                  HingeJoint {
                    jointParameters HingeJointParameters {
                      anchor 0.034200 -0.061999 -0.006001
                    }
                    device [
                      RotationalMotor {
                        name "right_shoulder_roll_joint"
                        maxVelocity 9.0
                        minPosition -3.4
                        maxPosition 0.38
                        maxTorque 40.0
                      }
                      PositionSensor {
                        name "right_shoulder_roll_joint_sensor"
                      }
                    ]
                    endPoint DEF right_shoulder_roll_link Solid {
                      translation 0.034200 -0.061999 -0.006001
                      rotation 1.000000 0.000000 0.000000 0.261800
                      children [
                        Shape {
                          appearance USE dark
                          geometry DEF right_shoulder_roll_link Mesh {
                            url "h1_2_description/meshes/right_shoulder_roll_link.STL"
                          }
                        }
                        HingeJoint {
                          jointParameters HingeJointParameters {
                            axis 0.000000 0.000000 1.000000
                            anchor -0.034200 0.000000 -0.145600
                          }
                          device [
                            RotationalMotor {
                              name "right_shoulder_yaw_joint"
                              maxVelocity 20.0
                              minPosition -3.01
                              maxPosition 2.66
                              maxTorque 18.0
                            }
                            PositionSensor {
                              name "right_shoulder_yaw_joint_sensor"
                            }
                          ]
                          endPoint DEF right_shoulder_yaw_link Solid {
                            translation -0.034200 0.000000 -0.145600
                            children [
                              Shape {
                                appearance USE dark
                                geometry DEF right_shoulder_yaw_link Mesh {
                                  url "h1_2_description/meshes/right_shoulder_yaw_link.STL"
                                }
                              }
                              HingeJoint {
                                jointParameters HingeJointParameters {
                                  axis 0.000000 1.000000 0.000000
                                  anchor 0.006000 -0.032900 -0.182000
                                }
                                device [
                                  RotationalMotor {
                                    name "right_elbow_joint"
                                    maxVelocity 20.0
                                    minPosition -0.95
                                    maxPosition 3.18
                                    maxTorque 18.0
                                  }
                                  PositionSensor {
                                    name "right_elbow_joint_sensor"
                                  }
                                ]
                                endPoint DEF right_elbow_link Solid {
                                  translation 0.006000 -0.032900 -0.182000
                                  children [
                                    Shape {
                                      appearance USE dark
                                      geometry DEF right_elbow_link Mesh {
                                        url "h1_2_description/meshes/right_elbow_link.STL"
                                      }
                                    }
                                    HingeJoint {
                                      jointParameters HingeJointParameters {
                                        anchor 0.121000 0.032900 -0.011000
                                      }
                                      device [
                                        RotationalMotor {
                                          name "right_wrist_roll_joint"
                                          maxVelocity 31.4
                                          minPosition -2.75
                                          maxPosition 3.01
                                          maxTorque 19.0
                                        }
                                        PositionSensor {
                                          name "right_wrist_roll_joint_sensor"
                                        }
                                      ]
                                      endPoint DEF right_wrist_roll_link Solid {
                                        translation 0.121000 0.032900 -0.011000
                                        children [
                                          Shape {
                                            appearance USE dark
                                            geometry DEF right_wrist_roll_link Mesh {
                                              url "h1_2_description/meshes/right_wrist_roll_link.STL"
                                            }
                                          }
                                          HingeJoint {
                                            jointParameters HingeJointParameters {
                                              axis 0.000000 1.000000 0.000000
                                              anchor 0.087000 0.000000 0.000000
                                            }
                                            device [
                                              RotationalMotor {
                                                name "right_wrist_pitch_joint"
                                                maxVelocity 31.4
                                                minPosition -0.4625
                                                maxPosition 0.4625
                                                maxTorque 19.0
                                              }
                                              PositionSensor {
                                                name "right_wrist_pitch_joint_sensor"
                                              }
                                            ]
                                            endPoint DEF right_wrist_pitch_link Solid {
                                              translation 0.087000 0.000000 0.000000
                                              children [
                                                Shape {
                                                  appearance USE dark
                                                  geometry DEF right_wrist_pitch_link Mesh {
                                                    url "h1_2_description/meshes/right_wrist_pitch_link.STL"
                                                  }
                                                }
                                                HingeJoint {
                                                  jointParameters HingeJointParameters {
                                                    axis 0.000000 0.000000 1.000000
                                                    anchor 0.020000 0.000000 0.000000
                                                  }
                                                  device [
                                                    RotationalMotor {
                                                      name "right_wrist_yaw_joint"
                                                      maxVelocity 31.4
                                                      minPosition -1.27
                                                      maxPosition 1.27
                                                      maxTorque 19.0
                                                    }
                                                    PositionSensor {
                                                      name "right_wrist_yaw_joint_sensor"
                                                    }
                                                  ]
                                                  endPoint DEF right_wrist_yaw_link Solid {
                                                    translation 0.020000 0.000000 0.000000
                                                    children [
                                                      Shape {
                                                        appearance USE dark
                                                        geometry USE wrist_yaw_link
                                                      }
                                                      DEF R_hand_base_link Solid {
                                                        translation 0.054000 0.000000 0.000000
                                                        rotation 0.707107 -0.707107 -0.000000 3.141593
                                                        children [
                                                          Shape {
                                                            appearance USE dark
                                                            geometry DEF R_hand_base_link Mesh {
                                                              url "h1_2_description/meshes/R_hand_base_link.STL"
                                                            }
                                                          }
                                                          HingeJoint {
                                                            jointParameters HingeJointParameters {
                                                              axis -0.000004 1.000000 -0.000000
                                                              anchor -0.016960 -0.069100 -0.020450
                                                            }
                                                            device [
                                                              RotationalMotor {
                                                                name "R_thumb_proximal_yaw_joint"
                                                                maxVelocity 0.5
                                                                minPosition -0.1
                                                                maxPosition 1.3
                                                                maxTorque 1.0
                                                              }
                                                              PositionSensor {
                                                                name "R_thumb_proximal_yaw_joint_sensor"
                                                              }
                                                            ]
                                                            endPoint DEF R_thumb_proximal_base Solid {
                                                              translation -0.016960 -0.069100 -0.020450
                                                              rotation 0.577350 -0.577350 0.577352 2.094399
                                                              children [
                                                                Shape {
                                                                  appearance USE dark
                                                                  geometry DEF link11_R Mesh {
                                                                    url "h1_2_description/meshes/link11_R.STL"
                                                                  }
                                                                }
                                                                HingeJoint {
                                                                  jointParameters HingeJointParameters {
                                                                    axis 0.279134 0.960252 -0.000004
                                                                    anchor -0.008810 0.010892 -0.009250
                                                                  }
                                                                  device [
                                                                    RotationalMotor {
                                                                      name "R_thumb_proximal_pitch_joint"
                                                                      maxVelocity 0.5
                                                                      minPosition -0.1
                                                                      maxPosition 0.6
                                                                      maxTorque 1.0
                                                                    }
                                                                    PositionSensor {
                                                                      name "R_thumb_proximal_pitch_joint_sensor"
                                                                    }
                                                                  ]
                                                                  endPoint DEF R_thumb_proximal Solid {
                                                                    translation -0.008810 0.010892 -0.009250
                                                                    rotation 0.100184 0.703551 0.703548 2.941892
                                                                    children [
                                                                      Shape {
                                                                        appearance USE dark
                                                                        geometry DEF link12_R Mesh {
                                                                          url "h1_2_description/meshes/link12_R.STL"
                                                                        }
                                                                      }
                                                                      HingeJoint {
                                                                        jointParameters HingeJointParameters {
                                                                          axis 0.000000 0.000000 1.000000
                                                                          anchor 0.044070 0.034553 -0.000800
                                                                        }
                                                                        device [
                                                                          RotationalMotor {
                                                                            name "R_thumb_intermediate_joint"
                                                                            maxVelocity 0.5
                                                                            maxPosition 0.8
                                                                            maxTorque 1.0
                                                                          }
                                                                          PositionSensor {
                                                                            name "R_thumb_intermediate_joint_sensor"
                                                                          }
                                                                        ]
                                                                        endPoint DEF R_thumb_intermediate Solid {
                                                                          translation 0.044070 0.034553 -0.000800
                                                                          children [
                                                                            Shape {
                                                                              appearance USE dark
                                                                              geometry DEF link13_R Mesh {
                                                                                url "h1_2_description/meshes/link13_R.STL"
                                                                              }
                                                                            }
                                                                            HingeJoint {
                                                                              jointParameters HingeJointParameters {
                                                                                axis 0.000000 0.000000 1.000000
                                                                                anchor 0.020248 0.010156 -0.001200
                                                                              }
                                                                              device [
                                                                                RotationalMotor {
                                                                                  name "R_thumb_distal_joint"
                                                                                  maxVelocity 0.5
                                                                                  maxPosition 1.2
                                                                                  maxTorque 1.0
                                                                                }
                                                                                PositionSensor {
                                                                                  name "R_thumb_distal_joint_sensor"
                                                                                }
                                                                              ]
                                                                              endPoint DEF R_thumb_distal Solid {
                                                                                translation 0.020248 0.010156 -0.001200
                                                                                children [
                                                                                  Shape {
                                                                                    appearance USE dark
                                                                                    geometry DEF link14_R Mesh {
                                                                                      url "h1_2_description/meshes/link14_R.STL"
                                                                                    }
                                                                                  }
                                                                                ]
                                                                                name "R_thumb_distal"
                                                                                boundingObject USE link14_R
                                                                                physics Physics {
                                                                                  density -1
                                                                                  mass 0.003344
                                                                                  centerOfMass [ 0.009289 0.004953 -0.006003 ]
                                                                                  inertiaMatrix [
                                                                                    1.363200e-07 1.405200e-07 2.002600e-07
                                                                                    -5.678800e-08 -9.276400e-11 -1.228300e-10
                                                                                  ]
                                                                                }
                                                                              }
                                                                            }
                                                                          ]
                                                                          name "R_thumb_intermediate"
                                                                          boundingObject USE link13_R
                                                                          physics Physics {
                                                                            density -1
                                                                            mass 0.003785
                                                                            centerOfMass [ 0.009554 -0.001628 -0.007200 ]
                                                                            inertiaMatrix [
                                                                              3.698100e-07 3.239400e-07 4.653100e-07
                                                                              -9.858100e-08 -4.746900e-12 1.093900e-12
                                                                            ]
                                                                          }
                                                                        }
                                                                      }
                                                                    ]
                                                                    name "R_thumb_proximal"
                                                                    boundingObject USE link12_R
                                                                    physics Physics {
                                                                      density -1
                                                                      mass 0.006607
                                                                      centerOfMass [ 0.021932 0.012785 -0.008039 ]
                                                                      inertiaMatrix [
                                                                        1.568600e-06 1.735300e-06 2.786000e-06
                                                                        -7.829600e-07 8.914300e-10 -1.019100e-09
                                                                      ]
                                                                    }
                                                                  }
                                                                }
                                                              ]
                                                              name "R_thumb_proximal_base"
                                                              boundingObject USE link11_R
                                                              physics Physics {
                                                                density -1
                                                                mass 0.001887
                                                                centerOfMass [ -0.004806 0.000938 -0.007570 ]
                                                                inertiaMatrix [
                                                                  5.816000e-08 7.916100e-08 6.743300e-08
                                                                  1.453900e-08 4.491000e-09 -1.872700e-09
                                                                ]
                                                              }
                                                            }
                                                          }
                                                          HingeJoint {
                                                            jointParameters HingeJointParameters {
                                                              axis 0.000000 0.034886 -0.999391
                                                              anchor 0.000285 -0.136530 -0.032268
                                                            }
                                                            device [
                                                              RotationalMotor {
                                                                name "R_index_proximal_joint"
                                                                maxVelocity 0.5
                                                                maxPosition 1.7
                                                                maxTorque 1.0
                                                              }
                                                              PositionSensor {
                                                                name "R_index_proximal_joint_sensor"
                                                              }
                                                            ]
                                                            endPoint DEF R_index_proximal Solid {
                                                              translation 0.000285 -0.136530 -0.032268
                                                              rotation -1.000000 0.000000 0.000000 3.106700
                                                              children [
                                                                Shape {
                                                                  appearance USE dark
                                                                  geometry DEF link15_R Mesh {
                                                                    url "h1_2_description/meshes/link15_R.STL"
                                                                  }
                                                                }
                                                                HingeJoint {
                                                                  jointParameters HingeJointParameters {
                                                                    axis 0.000000 0.000000 1.000000
                                                                    anchor -0.002614 0.032026 -0.001000
                                                                  }
                                                                  device [
                                                                    RotationalMotor {
                                                                      name "R_index_intermediate_joint"
                                                                      maxVelocity 0.5
                                                                      maxPosition 1.7
                                                                      maxTorque 1.0
                                                                    }
                                                                    PositionSensor {
                                                                      name "R_index_intermediate_joint_sensor"
                                                                    }
                                                                  ]
                                                                  endPoint DEF R_index_intermediate Solid {
                                                                    translation -0.002614 0.032026 -0.001000
                                                                    children [
                                                                      Shape {
                                                                        appearance USE dark
                                                                        geometry DEF link16_R Mesh {
                                                                          url "h1_2_description/meshes/link16_R.STL"
                                                                        }
                                                                      }
                                                                    ]
                                                                    name "R_index_intermediate"
                                                                    boundingObject USE link16_R
                                                                    physics Physics {
                                                                      density -1
                                                                      mass 0.004568
                                                                      centerOfMass [ 0.001970 0.019589 -0.005000 ]
                                                                      inertiaMatrix [
                                                                        7.611100e-07 9.607600e-08 7.817900e-07
                                                                        8.763700e-08 -3.775100e-13 9.944400e-13
                                                                      ]
                                                                    }
                                                                  }
                                                                }
                                                              ]
                                                              name "R_index_proximal"
                                                              boundingObject USE link15_R
                                                              physics Physics {
                                                                density -1
                                                                mass 0.004240
                                                                centerOfMass [ 0.001226 0.011942 -0.006000 ]
                                                                inertiaMatrix [
                                                                  6.623200e-07 2.114600e-07 6.939800e-07
                                                                  -1.577500e-08 1.851500e-12 -5.082800e-12
                                                                ]
                                                              }
                                                            }
                                                          }
                                                          HingeJoint {
                                                            jointParameters HingeJointParameters {
                                                              axis 0.000000 -0.000007 -1.000000
                                                              anchor 0.000285 -0.137100 -0.012950
                                                            }
                                                            device [
                                                              RotationalMotor {
                                                                name "R_middle_proximal_joint"
                                                                maxVelocity 0.5
                                                                maxPosition 1.7
                                                                maxTorque 1.0
                                                              }
                                                              PositionSensor {
                                                                name "R_middle_proximal_joint_sensor"
                                                              }
                                                            ]
                                                            endPoint DEF R_middle_proximal Solid {
                                                              translation 0.000285 -0.137100 -0.012950
                                                              rotation -1.000000 -0.000000 0.000000 3.141600
                                                              children [
                                                                Shape {
                                                                  appearance USE dark
                                                                  geometry DEF link17_R Mesh {
                                                                    url "h1_2_description/meshes/link17_R.STL"
                                                                  }
                                                                }
                                                                HingeJoint {
                                                                  jointParameters HingeJointParameters {
                                                                    axis 0.000000 0.000000 1.000000
                                                                    anchor -0.002423 0.032041 -0.001000
                                                                  }
                                                                  device [
                                                                    RotationalMotor {
                                                                      name "R_middle_intermediate_joint"
                                                                      maxVelocity 0.5
                                                                      maxPosition 1.7
                                                                      maxTorque 1.0
                                                                    }
                                                                    PositionSensor {
                                                                      name "R_middle_intermediate_joint_sensor"
                                                                    }
                                                                  ]
                                                                  endPoint DEF R_middle_intermediate Solid {
                                                                    translation -0.002423 0.032041 -0.001000
                                                                    children [
                                                                      Shape {
                                                                        appearance USE dark
                                                                        geometry DEF link18_R Mesh {
                                                                          url "h1_2_description/meshes/link18_R.STL"
                                                                        }
                                                                      }
                                                                    ]
                                                                    name "R_middle_intermediate"
                                                                    boundingObject USE link18_R
                                                                    physics Physics {
                                                                      density -1
                                                                      mass 0.005040
                                                                      centerOfMass [ 0.001921 0.020796 -0.005000 ]
                                                                      inertiaMatrix [
                                                                        9.582200e-07 1.064600e-07 9.838400e-07
                                                                        1.142500e-07 -2.479100e-12 5.917300e-12
                                                                      ]
                                                                    }
                                                                  }
                                                                }
                                                              ]
                                                              name "R_middle_proximal"
                                                              boundingObject USE link17_R
                                                              physics Physics {
                                                                density -1
                                                                mass 0.004240
                                                                centerOfMass [ 0.001297 0.011934 -0.006000 ]
                                                                inertiaMatrix [
                                                                  6.621100e-07 2.116700e-07 6.939700e-07
                                                                  -1.846100e-08 1.800200e-12 -6.680800e-12
                                                                ]
                                                              }
                                                            }
                                                          }
                                                          HingeJoint {
                                                            jointParameters HingeJointParameters {
                                                              axis 0.000000 -0.052369 -0.998628
                                                              anchor 0.000285 -0.136910 0.006287
                                                            }
                                                            device [
                                                              RotationalMotor {
                                                                name "R_ring_proximal_joint"
                                                                maxVelocity 0.5
                                                                maxPosition 1.7
                                                                maxTorque 1.0
                                                              }
                                                              PositionSensor {
                                                                name "R_ring_proximal_joint_sensor"
                                                              }
                                                            ]
                                                            endPoint DEF R_ring_proximal Solid {
                                                              translation 0.000285 -0.136910 0.006287
                                                              rotation 1.000000 0.000000 0.000000 3.089200
                                                              children [
                                                                Shape {
                                                                  appearance USE dark
                                                                  geometry DEF link19_R Mesh {
                                                                    url "h1_2_description/meshes/link19_R.STL"
                                                                  }
                                                                }
                                                                HingeJoint {
                                                                  jointParameters HingeJointParameters {
                                                                    axis 0.000000 0.000000 1.000000
                                                                    anchor -0.002423 0.032041 -0.001000
                                                                  }
                                                                  device [
                                                                    RotationalMotor {
                                                                      name "R_ring_intermediate_joint"
                                                                      maxVelocity 0.5
                                                                      maxPosition 1.7
                                                                      maxTorque 1.0
                                                                    }
                                                                    PositionSensor {
                                                                      name "R_ring_intermediate_joint_sensor"
                                                                    }
                                                                  ]
                                                                  endPoint DEF R_ring_intermediate Solid {
                                                                    translation -0.002423 0.032041 -0.001000
                                                                    children [
                                                                      Shape {
                                                                        appearance USE dark
                                                                        geometry DEF link20_R Mesh {
                                                                          url "h1_2_description/meshes/link20_R.STL"
                                                                        }
                                                                      }
                                                                    ]
                                                                    name "R_ring_intermediate"
                                                                    boundingObject USE link20_R
                                                                    physics Physics {
                                                                      density -1
                                                                      mass 0.004568
                                                                      centerOfMass [ 0.002175 0.019567 -0.005000 ]
                                                                      inertiaMatrix [
                                                                        7.628600e-07 9.431000e-08 7.817700e-07
                                                                        8.063500e-08 -6.156200e-13 5.861900e-13
                                                                      ]
                                                                    }
                                                                  }
                                                                }
                                                              ]
                                                              name "R_ring_proximal"
                                                              boundingObject USE link19_R
                                                              physics Physics {
                                                                density -1
                                                                mass 0.004240
                                                                centerOfMass [ 0.001297 0.011934 -0.006000 ]
                                                                inertiaMatrix [
                                                                  6.621100e-07 2.116700e-07 6.939700e-07
                                                                  -1.846100e-08 1.579300e-12 -6.686800e-12
                                                                ]
                                                              }
                                                            }
                                                          }
                                                          HingeJoint {
                                                            jointParameters HingeJointParameters {
                                                              axis 0.000000 -0.104502 -0.994525
                                                              anchor 0.000285 -0.135710 0.025488
                                                            }
                                                            device [
                                                              RotationalMotor {
                                                                name "R_pinky_proximal_joint"
                                                                maxVelocity 0.5
                                                                maxPosition 1.7
                                                                maxTorque 1.0
                                                              }
                                                              PositionSensor {
                                                                name "R_pinky_proximal_joint_sensor"
                                                              }
                                                            ]
                                                            endPoint DEF R_pinky_proximal Solid {
                                                              translation 0.000285 -0.135710 0.025488
                                                              rotation 1.000000 0.000000 0.000000 3.036900
                                                              children [
                                                                Shape {
                                                                  appearance USE dark
                                                                  geometry DEF link21_R Mesh {
                                                                    url "h1_2_description/meshes/link21_R.STL"
                                                                  }
                                                                }
                                                                HingeJoint {
                                                                  jointParameters HingeJointParameters {
                                                                    axis 0.000000 0.000000 1.000000
                                                                    anchor -0.002423 0.032041 -0.001000
                                                                  }
                                                                  device [
                                                                    RotationalMotor {
                                                                      name "R_pinky_intermediate_joint"
                                                                      maxVelocity 0.5
                                                                      maxPosition 1.7
                                                                      maxTorque 1.0
                                                                    }
                                                                    PositionSensor {
                                                                      name "R_pinky_intermediate_joint_sensor"
                                                                    }
                                                                  ]
                                                                  endPoint DEF R_pinky_intermediate Solid {
                                                                    translation -0.002423 0.032041 -0.001000
                                                                    children [
                                                                      Shape {
                                                                        appearance USE dark
                                                                        geometry DEF link22_R Mesh {
                                                                          url "h1_2_description/meshes/link22_R.STL"
                                                                        }
                                                                      }
                                                                    ]
                                                                    name "R_pinky_intermediate"
                                                                    boundingObject USE link22_R
                                                                    physics Physics {
                                                                      density -1
                                                                      mass 0.003600
                                                                      centerOfMass [ 0.002475 0.016203 -0.005003 ]
                                                                      inertiaMatrix [
                                                                        4.391300e-07 7.024700e-08 4.486700e-07
                                                                        4.141800e-08 3.716800e-11 5.861300e-11
                                                                      ]
                                                                    }
                                                                  }
                                                                }
                                                              ]
                                                              name "R_pinky_proximal"
                                                              boundingObject USE link21_R
                                                              physics Physics {
                                                                density -1
                                                                mass 0.004240
                                                                centerOfMass [ 0.001297 0.011934 -0.006000 ]
                                                                inertiaMatrix [
                                                                  6.621100e-07 2.116700e-07 6.939700e-07
                                                                  -1.846100e-08 1.690700e-12 -6.933400e-12
                                                                ]
                                                              }
                                                            }
                                                          }
                                                        ]
                                                        name "R_hand_base_link"
                                                        boundingObject USE R_hand_base_link
                                                        physics Physics {
                                                          density -1
                                                          mass 0.141430
                                                          centerOfMass [ -0.002526 -0.066047 0.001960 ]
                                                          inertiaMatrix [
                                                            1.228100e-04 8.383200e-05 7.666300e-05
                                                            2.171100e-06 1.770900e-06 -1.655100e-06
                                                          ]
                                                        }
                                                      }
                                                    ]
                                                    name "right_wrist_yaw_link"
                                                    physics Physics {
                                                      density -1
                                                      mass 0.124000
                                                      centerOfMass [ 0.027967 -0.000096 0.000739 ]
                                                      inertiaMatrix [
                                                        1.373000e-04 1.699980e-04 8.480800e-05
                                                        1.710000e-07 2.942000e-06 2.500000e-08
                                                      ]
                                                    }
                                                  }
                                                }
                                              ]
                                              name "right_wrist_pitch_link"
                                              boundingObject USE right_wrist_pitch_link
                                              physics Physics {
                                                density -1
                                                mass 0.484000
                                                centerOfMass [ 0.020395 0.000036 -0.002973 ]
                                                inertiaMatrix [
                                                  7.136400e-05 6.991500e-05 7.070200e-05
                                                  3.080000e-07 1.485000e-06 -8.800000e-08
                                                ]
                                              }
                                            }
                                          }
                                        ]
                                        name "right_wrist_roll_link"
                                        boundingObject USE right_wrist_roll_link
                                        physics Physics {
                                          density -1
                                          mass 0.683000
                                          centerOfMass [ 0.035281 -0.002320 0.000337 ]
                                          inertiaMatrix [
                                            3.132750e-04 3.104120e-04 3.459980e-04
                                            1.652100e-05 -2.501000e-06 5.435000e-06
                                          ]
                                        }
                                      }
                                    }
                                  ]
                                  name "right_elbow_link"
                                  boundingObject USE right_elbow_link
                                  physics Physics {
                                    density -1
                                    mass 0.691000
                                    centerOfMass [ 0.077092 0.028751 -0.009714 ]
                                    inertiaMatrix [
                                      3.184910e-04 8.612240e-04 8.978990e-04
                                      -2.245540e-04 6.620760e-05 2.332900e-05
                                    ]
                                  }
                                }
                              }
                            ]
                            name "right_shoulder_yaw_link"
                            boundingObject USE right_shoulder_yaw_link
                            physics Physics {
                              density -1
                              mass 1.505000
                              centerOfMass [ 0.004583 -0.001128 -0.001128 ]
                              inertiaMatrix [
                                4.199000e-03 4.313900e-03 6.575500e-04
                                1.778600e-05 1.837200e-04 -9.278000e-05
                              ]
                            }
                          }
                        }
                      ]
                      name "right_shoulder_roll_link"
                      boundingObject USE right_shoulder_roll_link
                      physics Physics {
                        density -1
                        mass 1.393000
                        centerOfMass [ -0.030932 0.000001 -0.106090 ]
                        inertiaMatrix [
                          1.840800e-03 1.934638e-03 6.177330e-04
                          -3.980000e-07 -4.832400e-04 -1.610000e-07
                        ]
                      }
                    }
                  }
                ]
                name "right_shoulder_pitch_link"
                boundingObject USE right_shoulder_pitch_link
                physics Physics {
                  density -1
                  mass 1.327000
                  centerOfMass [ 0.003053 -0.060420 -0.005900 ]
                  inertiaMatrix [
                    5.866100e-04 3.989000e-04 5.293600e-04
                    2.015700e-05 2.985000e-06 -2.238000e-05
                  ]
                }
              }
            }
          ]
          name "torso_link"
          boundingObject Box {
             size 0.080000 0.160000 0.100000
          }
          physics Physics {
            density -1
            mass 17.789000
            centerOfMass [ 0.000489 0.002797 0.204840 ]
            inertiaMatrix [
              4.873000e-01 4.096300e-01 1.278500e-01
              -5.376300e-04 2.027600e-03 -7.458200e-04
            ]
          }
        }
      }
    ]
    name IS name
    boundingObject Sphere {
      radius 0.05
    }
    physics Physics {
      density -1
      mass 5.983000
      centerOfMass [ -0.000400 0.000037 -0.046864 ]
      inertiaMatrix [
        4.916841e-02 9.025844e-03 5.315589e-02
        -1.986900e-05 -4.846000e-05 3.431000e-06
      ]
    }
  }
}
